const main = async () => {
  const a: 1 = 1;
  console.log(a);
};

main().catch(err => console.log(`Something bad happened: ${err}`));
