

const main = async () => {
  
};

main().catch(err => console.log(`Something bad happened: ${err}`));
